<?xml version="1.0"?>
<robot xmlns:xacro="http://www.ros.org/wiki/xacro" name="Robot1">
<link name="upper_link">
    <visual>
      <geometry>
<!-- <mesh filename="package://head_meka_description/meshes/BASE_CATPART.stl"/>-->
        <mesh filename="package://head_meka_description/meshes/Arriba.stl" scale="0.001 0.001 0.001"/>
      </geometry>
      <origin rpy="0 0 0" xyz="0 0 -0.182"/>
      <material name="white">
        <color rgba="1 1 1 1"/>
      </material>
    </visual>
  </link>

<link name="medium_link">
    <visual>
      <geometry>
        <mesh filename="package://head_meka_description/meshes/Medio.stl" scale="0.001 0.001 0.001"/>
      </geometry>
      <origin rpy="0 0 0" xyz="0 0 -0.182"/>
      <material name="white">
        <color rgba="1 1 1 1"/>
      </material>
    </visual>
  </link>

<link name="head_base_link">
      <visual>
      <geometry>
        <mesh filename="package://head_meka_description/meshes/Base.stl" scale="0.001 0.001 0.001"/>
      </geometry>
      <origin rpy="0 0 0" xyz="0 0 0"/>
      <material name="white">
        <color rgba="1 1 1 1"/>
      </material>
    </visual>
  </link>


  <joint name="base_to_medium" type="revolute">
    <axis xyz="0 0 1" />
    <limit
      lower="-1.5707"
      upper="1.5707"
      effort="5"
      velocity="1" />
   <parent link="head_base_link"/>
     <child link="medium_link"/>
     <origin xyz="0 0 0.184"/>
   </joint>

  <joint name="medium_to_upp" type="revolute">
    <axis xyz="1 0 0" />
    <limit
      lower="-0.9"
      upper="0.9"
      effort="5"
      velocity="1" />
   <parent link="medium_link"/>
     <child link="upper_link"/>
     <origin xyz="0 0 0"/>
   </joint>

  <xacro:include filename="$(find head_meka_description)/urdf/kinect_head.urdf.xacro" />


</robot>
